<robot name="onshape">
<link name="base_motor">
<visual>
<geometry>
<mesh filename="package://483c803918afc4d52e2647f0_e1ea9a2d18bfd7e78c6c1cef_12b0ecf57e5bc30e6e0147a2_JHD.stl"/>
</geometry>
<origin xyz="0 0 0" rpy="0 0 0"/>
</visual>
<collision>
<geometry>
<mesh filename="package://483c803918afc4d52e2647f0_e1ea9a2d18bfd7e78c6c1cef_12b0ecf57e5bc30e6e0147a2_JHD.stl"/>
</geometry>
<origin xyz="0 0 0" rpy="0 0 0"/>
</collision>
<inertial>
<origin xyz="0.012059 0.000000 0.000000" rpy="0 0 0"/>
<mass value="0.025907"/>
<inertia ixx="0.000003" ixy="0.000000"  ixz="0.000000" iyy="0.000005" iyz="0.000000" izz="0.000005" />
</inertial>
</link>
<link name="MGjZ9R5GABgEa7xE6_MRmWGwrqqKm6046h4_MrTaIPakjAtDOkFNZ">
<visual>
<geometry>
<mesh filename="package://483c803918afc4d52e2647f0_e1ea9a2d18bfd7e78c6c1cef_82b5ca5a5a1b4e7b48cea9b1_JHD.stl"/>
</geometry>
<origin xyz="0 0 0" rpy="0 0 0"/>
</visual>
<collision>
<geometry>
<mesh filename="package://483c803918afc4d52e2647f0_e1ea9a2d18bfd7e78c6c1cef_82b5ca5a5a1b4e7b48cea9b1_JHD.stl"/>
</geometry>
<origin xyz="0 0 0" rpy="0 0 0"/>
</collision>
<inertial>
<origin xyz="-0.000000 0.000000 0.001000" rpy="0 0 0"/>
<mass value="0.000993"/>
<inertia ixx="0.000000" ixy="0.000000"  ixz="0.000000" iyy="0.000000" iyz="0.000000" izz="0.000000" />
</inertial>
</link>
<joint name="MGjZ9R5GABgEa7xE6_MRmWGwrqqKm6046h4_MrTaIPakjAtDOkFNZ_fixing" type="fixed">
<origin xyz="0.000000 -0.000000 -0.014500" rpy="0.000000 -0.000000 0.510765" />
<parent link="base_motor"/>
<child link="MGjZ9R5GABgEa7xE6_MRmWGwrqqKm6046h4_MrTaIPakjAtDOkFNZ"/>
<axis xyz="0 0 0"/>
</joint>

<link name="MGjZ9R5GABgEa7xE6_MuBTvu6a0ybd4K0xz">
<visual>
<geometry>
<mesh filename="package://483c803918afc4d52e2647f0_e1ea9a2d18bfd7e78c6c1cef_20b15279700833ebd3858b10_JID.stl"/>
</geometry>
<origin xyz="0 0 0" rpy="0 0 0"/>
</visual>
<collision>
<geometry>
<mesh filename="package://483c803918afc4d52e2647f0_e1ea9a2d18bfd7e78c6c1cef_20b15279700833ebd3858b10_JID.stl"/>
</geometry>
<origin xyz="0 0 0" rpy="0 0 0"/>
</collision>
<inertial>
<origin xyz="-0.000000 0.055554 0.000000" rpy="0 0 0"/>
<mass value="0.029061"/>
<inertia ixx="0.000016" ixy="0.000000"  ixz="0.000000" iyy="0.000005" iyz="0.000000" izz="0.000015" />
</inertial>
</link>
<joint name="MGjZ9R5GABgEa7xE6_MuBTvu6a0ybd4K0xz_fixing" type="fixed">
<origin xyz="0.016971 0.000000 0.000000" rpy="0.000000 -0.000000 -1.570796" />
<parent link="base_motor"/>
<child link="MGjZ9R5GABgEa7xE6_MuBTvu6a0ybd4K0xz"/>
<axis xyz="0 0 0"/>
</joint>

<link name="MGjZ9R5GABgEa7xE6_MRmWGwrqqKm6046h4_MSM0yBoSlvssFTolC">
<visual>
<geometry>
<mesh filename="package://483c803918afc4d52e2647f0_e1ea9a2d18bfd7e78c6c1cef_82b5ca5a5a1b4e7b48cea9b1_JMD.stl"/>
</geometry>
<origin xyz="0 0 0" rpy="0 0 0"/>
</visual>
<collision>
<geometry>
<mesh filename="package://483c803918afc4d52e2647f0_e1ea9a2d18bfd7e78c6c1cef_82b5ca5a5a1b4e7b48cea9b1_JMD.stl"/>
</geometry>
<origin xyz="0 0 0" rpy="0 0 0"/>
</collision>
<inertial>
<origin xyz="-0.000000 0.000000 0.026000" rpy="0 0 0"/>
<mass value="0.000993"/>
<inertia ixx="0.000000" ixy="0.000000"  ixz="0.000000" iyy="0.000000" iyz="0.000000" izz="0.000000" />
</inertial>
</link>
<joint name="MGjZ9R5GABgEa7xE6_MRmWGwrqqKm6046h4_MSM0yBoSlvssFTolC_fixing" type="fixed">
<origin xyz="0.000000 -0.000000 -0.012500" rpy="0.000000 -0.000000 0.000000" />
<parent link="base_motor"/>
<child link="MGjZ9R5GABgEa7xE6_MRmWGwrqqKm6046h4_MSM0yBoSlvssFTolC"/>
<axis xyz="0 0 0"/>
</joint>

<link name="doublearm">
<visual>
<geometry>
<mesh filename="package://483c803918afc4d52e2647f0_e1ea9a2d18bfd7e78c6c1cef_afc7f875c2b191985111a8c1_JSD.stl"/>
</geometry>
<origin xyz="0 0 0" rpy="0 0 0"/>
</visual>
<collision>
<geometry>
<mesh filename="package://483c803918afc4d52e2647f0_e1ea9a2d18bfd7e78c6c1cef_afc7f875c2b191985111a8c1_JSD.stl"/>
</geometry>
<origin xyz="0 0 0" rpy="0 0 0"/>
</collision>
<inertial>
<origin xyz="0.023650 0.000000 -0.000085" rpy="0 0 0"/>
<mass value="0.011180"/>
<inertia ixx="0.000003" ixy="0.000000"  ixz="-0.000000" iyy="0.000008" iyz="0.000000" izz="0.000005" />
</inertial>
</link>
<link name="MHvYn9WYZ+qvCUHOv_MSxm2O0jahJJKepaP">
<visual>
<geometry>
<mesh filename="package://483c803918afc4d52e2647f0_e1ea9a2d18bfd7e78c6c1cef_82b5ca5a5a1b4e7b48cea9b1_JMD.stl"/>
</geometry>
<origin xyz="0 0 0" rpy="0 0 0"/>
</visual>
<collision>
<geometry>
<mesh filename="package://483c803918afc4d52e2647f0_e1ea9a2d18bfd7e78c6c1cef_82b5ca5a5a1b4e7b48cea9b1_JMD.stl"/>
</geometry>
<origin xyz="0 0 0" rpy="0 0 0"/>
</collision>
<inertial>
<origin xyz="-0.000000 0.000000 0.026000" rpy="0 0 0"/>
<mass value="0.000993"/>
<inertia ixx="0.000000" ixy="0.000000"  ixz="0.000000" iyy="0.000000" iyz="0.000000" izz="0.000000" />
</inertial>
</link>
<joint name="MHvYn9WYZ+qvCUHOv_MSxm2O0jahJJKepaP_fixing" type="fixed">
<origin xyz="0.000000 0.000000 -0.007500" rpy="0.000000 -0.000000 3.116984" />
<parent link="doublearm"/>
<child link="MHvYn9WYZ+qvCUHOv_MSxm2O0jahJJKepaP"/>
<axis xyz="0 0 0"/>
</joint>

<link name="MHvYn9WYZ+qvCUHOv_MMUKTvSIXyOSp6L9W">
<visual>
<geometry>
<mesh filename="package://483c803918afc4d52e2647f0_e1ea9a2d18bfd7e78c6c1cef_afc7f875c2b191985111a8c1_JSD.stl"/>
</geometry>
<origin xyz="0 0 0" rpy="0 0 0"/>
</visual>
<collision>
<geometry>
<mesh filename="package://483c803918afc4d52e2647f0_e1ea9a2d18bfd7e78c6c1cef_afc7f875c2b191985111a8c1_JSD.stl"/>
</geometry>
<origin xyz="0 0 0" rpy="0 0 0"/>
</collision>
<inertial>
<origin xyz="0.023650 0.000000 -0.000085" rpy="0 0 0"/>
<mass value="0.011180"/>
<inertia ixx="0.000003" ixy="0.000000"  ixz="-0.000000" iyy="0.000008" iyz="0.000000" izz="0.000005" />
</inertial>
</link>
<joint name="MHvYn9WYZ+qvCUHOv_MMUKTvSIXyOSp6L9W_fixing" type="fixed">
<origin xyz="0.116000 0.012500 0.012500" rpy="1.570796 -0.000000 -3.141593" />
<parent link="doublearm"/>
<child link="MHvYn9WYZ+qvCUHOv_MMUKTvSIXyOSp6L9W"/>
<axis xyz="0 0 0"/>
</joint>

<link name="Mu5ZC5G4J0M4U3zp8_Milb7cUQqZAWWVV8J">
<visual>
<geometry>
<mesh filename="package://483c803918afc4d52e2647f0_e1ea9a2d18bfd7e78c6c1cef_12b0ecf57e5bc30e6e0147a2_JHD.stl"/>
</geometry>
<origin xyz="0 0 0" rpy="0 0 0"/>
</visual>
<collision>
<geometry>
<mesh filename="package://483c803918afc4d52e2647f0_e1ea9a2d18bfd7e78c6c1cef_12b0ecf57e5bc30e6e0147a2_JHD.stl"/>
</geometry>
<origin xyz="0 0 0" rpy="0 0 0"/>
</collision>
<inertial>
<origin xyz="0.012059 0.000000 0.000000" rpy="0 0 0"/>
<mass value="0.025907"/>
<inertia ixx="0.000003" ixy="0.000000"  ixz="0.000000" iyy="0.000005" iyz="0.000000" izz="0.000005" />
</inertial>
</link>
<joint name="Mu5ZC5G4J0M4U3zp8_Milb7cUQqZAWWVV8J_fixing" type="fixed">
<origin xyz="0.000000 -0.000000 0.014500" rpy="-0.000000 0.000000 2.719345" />
<parent link="motor_horn"/>
<child link="Mu5ZC5G4J0M4U3zp8_Milb7cUQqZAWWVV8J"/>
<axis xyz="0 0 0"/>
</joint>

<link name="Mu5ZC5G4J0M4U3zp8_MSM0yBoSlvssFTolC">
<visual>
<geometry>
<mesh filename="package://483c803918afc4d52e2647f0_e1ea9a2d18bfd7e78c6c1cef_82b5ca5a5a1b4e7b48cea9b1_JMD.stl"/>
</geometry>
<origin xyz="0 0 0" rpy="0 0 0"/>
</visual>
<collision>
<geometry>
<mesh filename="package://483c803918afc4d52e2647f0_e1ea9a2d18bfd7e78c6c1cef_82b5ca5a5a1b4e7b48cea9b1_JMD.stl"/>
</geometry>
<origin xyz="0 0 0" rpy="0 0 0"/>
</collision>
<inertial>
<origin xyz="-0.000000 0.000000 0.026000" rpy="0 0 0"/>
<mass value="0.000993"/>
<inertia ixx="0.000000" ixy="0.000000"  ixz="0.000000" iyy="0.000000" iyz="0.000000" izz="0.000000" />
</inertial>
</link>
<joint name="Mu5ZC5G4J0M4U3zp8_MSM0yBoSlvssFTolC_fixing" type="fixed">
<origin xyz="0.000000 -0.000000 0.002000" rpy="0.000000 -0.000000 -0.392388" />
<parent link="motor_horn"/>
<child link="Mu5ZC5G4J0M4U3zp8_MSM0yBoSlvssFTolC"/>
<axis xyz="0 0 0"/>
</joint>

<link name="motor_horn">
<visual>
<geometry>
<mesh filename="package://483c803918afc4d52e2647f0_e1ea9a2d18bfd7e78c6c1cef_82b5ca5a5a1b4e7b48cea9b1_JHD.stl"/>
</geometry>
<origin xyz="0 0 0" rpy="0 0 0"/>
</visual>
<collision>
<geometry>
<mesh filename="package://483c803918afc4d52e2647f0_e1ea9a2d18bfd7e78c6c1cef_82b5ca5a5a1b4e7b48cea9b1_JHD.stl"/>
</geometry>
<origin xyz="0 0 0" rpy="0 0 0"/>
</collision>
<inertial>
<origin xyz="-0.000000 0.000000 0.001000" rpy="0 0 0"/>
<mass value="0.000993"/>
<inertia ixx="0.000000" ixy="0.000000"  ixz="0.000000" iyy="0.000000" iyz="0.000000" izz="0.000000" />
</inertial>
</link>
<joint name="doublearm_motor_horn" type="revolute">
<origin xyz="0.116000 0.027000 0.012500" rpy="-1.570796 0.367779 3.141593" />
<parent link="doublearm" />
<child link="motor_horn" />
<axis xyz="0 0 1"/>
<limit effort="0.5" velocity="12.5664" />
<joint_properties friction="0.0"/>
</joint>

<joint name="base_motor_doublearm" type="revolute">
<origin xyz="0.000000 0.000000 0.000000" rpy="0.000000 -0.000000 -3.116984" />
<parent link="base_motor" />
<child link="doublearm" />
<axis xyz="0 0 1"/>
<limit effort="0.5" velocity="12.5664" />
<joint_properties friction="0.0"/>
</joint>

</robot>
